Workbook

Sheet Roster & Stats
A1: Player Info | F1: Games, W/L | I1: Points
A2: Ranking | B2: First | C2: Last | D2: Email | E2: Venmo | F2: Games Played | G2: Wins | H2: Losses | I2: Week 1 | J2: Week 2 | K2: Total Points
A3: 1 | B3: Andrew | C3: Nix | D3: andrew.nix@mail.wvu.edu | E3: Andrew-Nix-10 | F3: =sum(G3:H3) -> 8 | G3: =sum('Week 1 (129)'!I31,'Week 2 (219)'!I29) -> 7 | H3: =sum('Week 1 (129)'!J31,'Week 2 (219)'!J29) -> 1 | I3: ='Week 1 (129)'!H31 -> 40 | J3: ='Week 2 (219)'!H29 -> 36 | K3: =sum(I3:J3) -> 76
A4: 2 | B4: Tyler | C4: Lannon | D4: tjl00023@mix.wvu.edu | E4: tlannon20 | F4: =sum(G4:H4) -> 8 | G4: =sum('Week 1 (129)'!I35,'Week 2 (219)'!I33) -> 5 | H4: =sum('Week 1 (129)'!J35,'Week 2 (219)'!J33) -> 3 | I4: ='Week 1 (129)'!H35 -> 37 | J4: ='Week 2 (219)'!H33 -> 31 | K4: =sum(I4:J4) -> 68
A5: 3 | B5: Dalton | C5: Wiggins | D5: dmw0034@mix.wvu.edu | E5: Daltonwiggins | F5: =sum(G5:H5) -> 8 | G5: =sum('Week 1 (129)'!I25,'Week 2 (219)'!I25) -> 5 | H5: =sum('Week 1 (129)'!J25,'Week 2 (219)'!J25) -> 3 | I5: ='Week 1 (129)'!H25 -> 33 | J5: ='Week 2 (219)'!H25 -> 30 | K5: =sum(I5:J5) -> 63
A6: 4 | B6: Olivia | C6: Irvine | D6: oli00001@mix.wvu.edu | E6: oirvine | F6: =sum(G6:H6) -> 8 | G6: =sum('Week 1 (129)'!I27,'Week 2 (219)'!I29) -> 4 | H6: =sum('Week 1 (129)'!J27,'Week 2 (219)'!J29) -> 4 | I6: ='Week 1 (129)'!H27 -> 26 | J6: ='Week 2 (219)'!H29 -> 36 | K6: =sum(I6:J6) -> 62
A7: 5 | B7: Levi | C7: Frashure | D7: lwf00003@mix.wvu.edu | E7: levifrashure | F7: =sum(G7:H7) -> 8 | G7: =sum('Week 1 (129)'!I33,'Week 2 (219)'!I27) -> 4 | H7: =sum('Week 1 (129)'!J33,'Week 2 (219)'!J27) -> 4 | I7: ='Week 1 (129)'!H33 -> 23 | J7: ='Week 2 (219)'!H27 -> 35 | K7: =sum(I7:J7) -> 58
A8: 6 | B8: Brian | C8: Woerner | D8: brian.woerner@mail.wvu.edu | E8: Brian-Woerner-2 | F8: =sum(G8:H8) -> 8 | G8: =sum('Week 1 (129)'!I35,'Week 2 (219)'!I31) -> 3 | H8: =sum('Week 1 (129)'!J35,'Week 2 (219)'!J31) -> 5 | I8: ='Week 1 (129)'!H35 -> 37 | J8: ='Week 2 (219)'!H31 -> 20 | K8: =sum(I8:J8) -> 57
A9: 7 | B9: Homer | C9: Butcher | D9: heb00002@mix.wvu.edu | E9: homerbutcher | F9: =sum(G9:H9) -> 8 | G9: =sum('Week 1 (129)'!I29,'Week 2 (219)'!I27) -> 3 | H9: =sum('Week 1 (129)'!J29,'Week 2 (219)'!J27) -> 5 | I9: ='Week 1 (129)'!H29 -> 19 | J9: ='Week 2 (219)'!H27 -> 35 | K9: =sum(I9:J9) -> 54
A10: 8 | B10: John | C10: Bittinger | D10: jmb00063@mix.wvu.edu | E10: Johnnybit730 | F10: =sum(G10:H10) -> 8 | G10: =sum('Week 1 (129)'!I29,'Week 2 (219)'!I33) -> 2 | H10: =sum('Week 1 (129)'!J29,'Week 2 (219)'!J33) -> 6 | I10: ='Week 1 (129)'!H29 -> 19 | J10: ='Week 2 (219)'!H33 -> 31 | K10: =sum(I10:J10) -> 50
A11: 9 | B11: Domenick | C11: Hoh | D11: dmh00018@mix.wvu.edu | E11: Domenick-Hoh | F11: =sum(G11:H11) -> 8 | G11: =sum('Week 1 (129)'!I33,'Week 2 (219)'!I31) -> 1 | H11: =sum('Week 1 (129)'!J33,'Week 2 (219)'!J31) -> 7 | I11: ='Week 1 (129)'!H33 -> 23 | J11: ='Week 2 (219)'!H31 -> 20 | K11: =sum(I11:J11) -> 43
A12: 10 | B12: Jared | C12: Behr | D12: jtb0032@mix.wvu.edu | E12: jared-behr-1 | F12: =sum(G12:H12) -> 4 | G12: =sum('Week 1 (129)'!I31) -> 4 | H12: =sum('Week 1 (129)'!J31) -> 0 | I12: ='Week 1 (129)'!H31 -> 40 | J12: 0 | K12: =sum(I12:J12) -> 40
A13: 11 | B13: Abraham | C13: Gherman | D13: arg00053@mix.wvu.edu | E13: AbrahamGherman | F13: =sum(G13:H13) -> 4 | G13: =sum('Week 2 (219)'!I23) -> 2 | H13: =sum('Week 2 (219)'!J23) -> 2 | I13: 0 | J13: ='Week 2 (219)'!H23 -> 34 | K13: =sum(I13:J13) -> 34
A14: 12 | B14: Eric | C14: Ristey | D14: ejr00015@mix.wvu.edu | E14: EricRistey | F14: =sum(G14:H14) -> 4 | G14: =sum('Week 1 (129)'!I25) -> 3 | H14: =sum('Week 1 (129)'!J25) -> 1 | I14: ='Week 1 (129)'!H25 -> 33 | J14: 0 | K14: =sum(I14:J14) -> 33
A15: 13 | B15: Demetrios | C15: Svingos | D15: dns00003@mix.wvu.edu | E15: DemetriosSvingos | F15: =sum(G15:H15) -> 4 | G15: =sum('Week 1 (129)'!I23) -> 2 | H15: =sum('Week 1 (129)'!J23) -> 2 | I15: ='Week 1 (129)'!H23 -> 31 | J15: 0 | K15: =sum(I15:J15) -> 31
A16: 13 | B16: Robert | C16: Gavlik | D16: rg00061@mix.wvu.edu | E16: robertgavlik | F16: =sum(G16:H16) -> 4 | G16: =sum('Week 1 (129)'!I23) -> 2 | H16: =sum('Week 1 (129)'!J23) -> 2 | I16: ='Week 1 (129)'!H23 -> 31 | J16: 0 | K16: =sum(I16:J16) -> 31
A17: 15 | B17: Ethan | C17: Boyd | D17: eb00021@mix.wvu.edu | E17: ehb131 | F17: =sum(G17:H17) -> 4 | G17: =sum('Week 1 (129)'!I27) -> 1 | H17: =sum('Week 1 (129)'!J27) -> 3 | I17: ='Week 1 (129)'!H27 -> 26 | J17: 0 | K17: =sum(I17:J17) -> 26
A18: 16 | B18: Glenn | C18: Eloriaga | D18: gre00004@mix.wvu.edu | E18: Glenn-Eloriaga | F18: =sum(G18:H18) -> 0 | G18: 0 | H18: 0 | I18: 0 | J18: 0 | K18: =sum(I18:J18) -> 0
A19: 16 | B19: Hunter | C19: Powell | D19: htp00004@mix.wvu.edu | F19: =sum(G19:H19) -> 0 | G19: 0 | H19: 0 | I19: 0 | J19: 0 | K19: =sum(I19:J19) -> 0
A20: 16 | B20: Nick | C20: Klug | D20: nklug@mail.wvu.edu | F20: =sum(G20:H20) -> 0 | G20: 0 | H20: 0 | I20: 0 | J20: 0 | K20: =sum(I20:J20) -> 0

Sheet Week 1 (129)
A1: Participants
A2: First | B2: Last | C2: Email | D2: Buy-In Paid
A3: Ethan | B3: Boyd | C3: eb00021@mix.wvu.edu
A4: Robert | B4: Gavlik | C4: rg00061@mix.wvu.edu
A5: Homer | B5: Butcher | C5: heb00002@mix.wvu.edu
A6: Olivia | B6: Irvine | C6: oli00001@mix.wvu.edu
A7: Brian | B7: Woerner | C7: brian.woerner@mail.wvu.edu
A8: Andrew | B8: Nix | C8: andrew.nix@mail.wvu.edu
A9: Demetrios | B9: Svingos | C9: dns00003@mix.wvu.edu
A10: Levi | B10: Frashure | C10: lwf00003@mix.wvu.edu
A11: Eric | B11: Ristey | C11: ejr00015@mix.wvu.edu
A12: John | B12: Bittinger | C12: jmb00063@mix.wvu.edu
A13: Domenick | B13: Hoh | C13: dmh00018@mix.wvu.edu
A14: Jared | B14: Behr | C14: jtb0032@mix.wvu.edu
... A16: Tyler | B16: Lannon | C16: tjl00023@mix.wvu.edu
A20: Partners
A21: # | B21: Names | D21: Points | I21: Stats
B22: First | C22: Last | D22: Match 1 | E22: Match 2 | F22: Match 3 | G22: Match 4 | H22: Total | I22: Wins | J22: Losses
A23: 1 | B23: Robert | C23: Gavlik | D23: 4 | E23: 7 | F23: 10 | G23: 10 | H23: =sum(D23:G23) -> 31 | I23: =countif(D23:G24,10) -> 2 | J23: =4-I23 -> 2
B24: Demetrios | C24: Svingos
A25: 2 | B25: Eric | C25: Ristey | D25: 10 | E25: 10 | F25: 10 | G25: 3 | H25: =sum(D25:G25) -> 33 | I25: =countif(D25:G26,10) -> 3 | J25: =4-I25 -> 1
B26: Dalton | C26: Wiggins
A27: 3 | B27: Olivia | C27: Irvine | D27: 10 | E27: 5 | F27: 6 | G27: 5 | H27: =sum(D27:G27) -> 26 | I27: =countif(D27:G28,10) -> 1 | J27: =4-I27 -> 3
B28: Ethan | C28: Boyd
A29: 4 | B29: Homer | C29: Butcher | D29: 4 | E29: 7 | F29: 7 | G29: 1 | H29: =sum(D29:G29) -> 19 | I29: =countif(D29:G30,10) -> 0 | J29: =4-I29 -> 4
B30: John | C30: Bittinger
A31: 5 | B31: Jared | C31: Behr | D31: 10 | E31: 10 | F31: 10 | G31: 10 | H31: =sum(D31:G31) -> 40 | I31: =countif(D31:G32,10) -> 4 | J31: =4-I31 -> 0
B32: Andrew | C32: Nix
A33: 6 | B33: Domenick | C33: Hoh | D33: 5 | E33: 3 | F33: 10 | G33: 5 | H33: =sum(D33:G33) -> 23 | I33: =countif(D33:G34,10) -> 1 | J33: =4-I33 -> 3
B34: Levi | C34: Frashure
A35: 7 | B35: Tyler | C35: Lannon | D35: 10 | E35: 10 | F35: 10 | G35: 7 | H35: =sum(D35:G35) -> 37 | I35: =countif(D35:G36,10) -> 3 | J35: =4-I35 -> 1
B36: Brian | C36: Woerner
A37: 8 | H37: =sum(D37:G37) -> 0 | I37: =countif(D37:G38,10) -> 0 | J37: =4-I37 -> 4
A40: Matchups | G40: Legend
A41: Set | B41: Team1 | C41: Team2 | E41: Status | H41: Not Started
A42: 1 | B42: 1 | C42: 2 | H42: In progress
B43: 3 | C43: 4 | H43: Completed
B44: 5 | C44: 6 | H44: Canceled
A45: 2 | B45: 1 | C45: 7
B46: 2 | C46: 3
...

Sheet Week 2 (219)
A1: Participants
A2: First | B2: Last | C2: Email | D2: Venmo | E2: Buy-In Paid
A5: Homer | B5: Butcher | C5: heb00002@mix.wvu.edu | D5: homerbutcher
A6: Olivia | B6: Irvine | C6: oli00001@mix.wvu.edu | D6: oirvine
A7: Brian | B7: Woerner | C7: brian.woerner@mail.wvu.edu | D7: Brian-Woerner-2
A8: John | B8: Bittinger | C8: jmb00063@mix.wvu.edu | D8: Johnnybit730
A9: Dalton | B9: Wiggins | C9: dmw0034@mix.wvu.edu | D9: Daltonwiggins
A10: Tyler | B10: Lannon | C10: tjl00023@mix.wvu.edu | D10: tlannon20
A11: Abraham | B11: Gherman | C11: arg00053@mix.wvu.edu | D11: AbrahamGherman
A12: Levi | B12: Frashure | C12: lwf00003@mix.wvu.edu | D12: levifrashure
A13: Domenick | B13: Hoh | C13: dmh00018@mix.wvu.edu | D13: Domenick-Hoh
A14: Andrew | B14: Nix | C14: andrew.nix@mail.wvu.edu | D14: Andrew-Nix-10
A20: Partners
A21: # | B21: Names | D21: Points | I21: Stats
B22: First | C22: Last | D22: Match 1 | E22: Match 2 | F22: Match 3 | G22: Match 4 | H22: Total | I22: Wins | J22: Losses
A23: 1 | D23: 10 | E23: 10 | F23: 7 | G23: 7 | H23: =sum(D23:G23) -> 34 | I23: =countif(D23:G24,10) -> 2 | J23: =4-I23 -> 2
B24: Abraham | C24: Gherman
A25: 2 | D25: 10 | E25: 6 | F25: 4 | G25: 10 | H25: =sum(D25:G25) -> 30 | I25: =countif(D25:G26,10) -> 2 | J25: =4-I25 -> 2
B26: Dalton | C26: Wiggins
A27: 3 | B27: Homer | C27: Butcher | D27: 5 | E27: 10 | F27: 10 | G27: 10 | H27: =sum(D27:G27) -> 35 | I27: =countif(D27:G28,10) -> 3 | J27: =4-I27 -> 1
B28: Levi | C28: Frashure
A29: 4 | B29: Olivia | C29: Irvine | D29: 10 | E29: 10 | F29: 10 | G29: 6 | H29: =sum(D29:G29) -> 36 | I29: =countif(D29:G30,10) -> 3 | J29: =4-I29 -> 1
B30: Andrew | C30: Nix
A31: 5 | B31: Brian | C31: Woerner | D31: 5 | E31: 4 | F31: 4 | G31: 7 | H31: =sum(D31:G31) -> 20 | I31: =countif(D31:G32,10) -> 0 | J31: =4-I31 -> 4
B32: Domenick | C32: Hoh
A33: 6 | B33: John | C33: Bittinger | D33: 5 | E33: 6 | F33: 10 | G33: 10 | H33: =sum(D33:G33) -> 31 | I33: =countif(D33:G34,10) -> 2 | J33: =4-I33 -> 2
B34: Tyler | C34: Lannon
A35: 7 | H35: =sum(D35:G35) -> 0 | I35: =countif(D35:G36,10) -> 0 | J35: =4-I35 -> 4
A37: 8 | H37: =sum(D37:G37) -> 0 | I37: =countif(D37:G38,10) -> 0 | J37: =4-I37 -> 4
A40: Matchups | G40: Legend
A41: Set | B41: Team1 | C41: Team2 | E41: Status | H41: Not Started
A42: 1 | B42: 1 | C42: 6 | H42: In progress
B43: 2 | C43: 5 | H43: Completed
B44: 3 | C44: 4 | H44: Canceled
A45: 2 | B45: 1 | C45: 5
B46: 6 | C46: 4
B47: 2 | C47: 3
A48: 3 | B48: 1 | C48: 4
B49: 5 | C49: 3
B50: 6 | C50: 2
...

Sheet Week 3 (226)
A1: Participants
A2: First | B2: Last | C2: Email | D2: Venmo | E2: Buy-In Paid
A3: Ethan | B3: Boyd | C3: eb00021@mix.wvu.edu | D3: ehb131
A4: Robert | B4: Gavlik | C4: rg00061@mix.wvu.edu | D4: robertgavlik
A5: Homer | B5: Butcher | C5: heb00002@mix.wvu.edu | D5: homerbutcher
A6: Brian | B6: Woerner | C6: brian.woerner@mail.wvu.edu | D6: Brian-Woerner-2
A7: John | B7: Bittinger | C7: jmb00063@mix.wvu.edu | D7: Johnnybit730
A8: Dalton | B8: Wiggins | C8: dmw0034@mix.wvu.edu | D8: Daltonwiggins
A9: Tyler | B9: Lannon | C9: tjl00023@mix.wvu.edu | D9: tlannon20
A10: Levi | B10: Frashure | C10: lwf00003@mix.wvu.edu | D10: levifrashure
A11: Domenick | B11: Hoh | C11: dmh00018@mix.wvu.edu | D11: Domenick-Hoh
A12: Andrew | B12: Nix | C12: andrew.nix@mail.wvu.edu | D12: Andrew-Nix-10
A20: Partners
A21: # | B21: Names | D21: Points | I21: Stats
B22: First | C22: Last | D22: Match 1 | E22: Match 2 | F22: Match 3 | G22: Match 4 | H22: Total | I22: Wins | J22: Losses
A23: 1 | H23: =sum(D23:G23) -> 0 | I23: =countif(D23:G24,10) -> 0 | J23: =4-I23 -> 4
A25: 2 | H25: =sum(D25:G25) -> 0 | I25: =countif(D25:G26,10) -> 0 | J25: =4-I25 -> 4
A27: 3 | H27: =sum(D27:G27) -> 0 | I27: =countif(D27:G28,10) -> 0 | J27: =4-I27 -> 4
A29: 4 | H29: =sum(D29:G29) -> 0 | I29: =countif(D29:G30,10) -> 0 | J29: =4-I29 -> 4
A31: 5 | H31: =sum(D31:G31) -> 0 | I31: =countif(D31:G32,10) -> 0 | J31: =4-I31 -> 4
A33: 6 | H33: =sum(D33:G33) -> 0 | I33: =countif(D33:G34,10) -> 0 | J33: =4-I33 -> 4
A35: 7 | H35: =sum(D35:G35) -> 0 | I35: =countif(D35:G36,10) -> 0 | J35: =4-I35 -> 4
A37: 8 | H37: =sum(D37:G37) -> 0 | I37: =countif(D37:G38,10) -> 0 | J37: =4-I37 -> 4
A40: Matchups | G40: Legend
A41: Set | B41: Team1 | C41: Team2 | E41: Status | H41: Not Started
A42: 1 | H42: In progress
H43: Completed
H44: Canceled
A45: 2
A48: 3
A51: 4
